ERROR:root:Exception in main()
Traceback (most recent call last):
  File "c:/Users/DE1119189/Desktop/Github/Fileserve_Observer/test3.py", line 14, in <module>
    exit(main())
NameError: name 'main' is not defined
ERROR:root:Exception in main()
Traceback (most recent call last):
  File "c:/Users/DE1119189/Desktop/Github/Fileserve_Observer/test3.py", line 14, in <module>
    exit(main())
NameError: name 'main' is not defined
